<?xml version="1.0"?>
<robot name="C:/Users/jl_gz/Downloads/Webots/Robot.urdf" xmlns:xacro="http://ros.org/wiki/xacro">
  <link name="base_link">
  </link>
  <joint name="RW" type="continuous">
    <parent link="base_link"/>
    <child link="solid(2)"/>
    <axis xyz="0.000001 0 -1"/>
    <limit effort="10" velocity="10"/>
    <origin xyz="0.062 0 0" rpy="-1.570799 1.239898 1.570793"/>
  </joint>
  <link name="solid(2)">
    <visual>
      <geometry>
        <cylinder radius="0.05" length="0.025"/>
      </geometry>
    </visual>
    <collision>
      <geometry>
        <cylinder radius="0.05" length="0.025"/>
      </geometry>
    </collision>
  </link>
  <joint name="LW" type="continuous">
    <parent link="base_link"/>
    <child link="solid(1)"/>
    <axis xyz="0.000001 0 -1"/>
    <limit effort="10" velocity="10"/>
    <origin xyz="-0.062 0 0" rpy="1.570797 0.563341 -1.570795"/>
  </joint>
  <link name="solid(1)">
    <visual>
      <geometry>
        <cylinder radius="0.05" length="0.025"/>
      </geometry>
    </visual>
    <collision>
      <geometry>
        <cylinder radius="0.05" length="0.025"/>
      </geometry>
    </collision>
  </link>
  <link name="RS">
  </link>
  <joint name="base_link_RS_joint" type="fixed">
    <parent link="base_link"/>
    <child link="RS"/>
    <origin xyz="0.015 -0.045 0" rpy="2.356192 1.570794 -2.356192"/>
  </joint>
  <link name="LS">
  </link>
  <joint name="base_link_LS_joint" type="fixed">
    <parent link="base_link"/>
    <child link="LS"/>
    <origin xyz="-0.015 -0.045 0" rpy="2.356192 1.570794 -2.356192"/>
  </joint>
  <link name="solid">
    <visual>
      <geometry>
        <cylinder radius="0.05" length="0.1"/>
      </geometry>
    </visual>
    <collision>
      <geometry>
        <cylinder radius="0.05" length="0.1"/>
      </geometry>
    </collision>
  </link>
  <joint name="base_link_solid_joint" type="fixed">
    <parent link="base_link"/>
    <child link="solid"/>
    <origin xyz="0 0 0.02" rpy="0 0 0"/>
  </joint>
  <link name="appearance">
  </link>
  <joint name="solid_appearance_joint" type="fixed">
    <parent link="solid"/>
    <child link="appearance"/>
    <origin xyz="0 0 0" rpy="0 0 0"/>
  </joint>
  <link name="appearance_0">
  </link>
  <joint name="solid_appearance_0_joint" type="fixed">
    <parent link="solid"/>
    <child link="appearance_0"/>
    <origin xyz="0 0 0" rpy="0 0 0"/>
  </joint>
  <link name="solid_1">
  </link>
  <joint name="solid_solid_1_joint" type="fixed">
    <parent link="solid"/>
    <child link="solid_1"/>
    <origin xyz="0 0 0.05" rpy="0 0 0"/>
  </joint>
  <link name="appearance_2">
  </link>
  <joint name="solid_1_appearance_2_joint" type="fixed">
    <parent link="solid_1"/>
    <child link="appearance_2"/>
    <origin xyz="0 0 0" rpy="0 0 0"/>
  </joint>
</robot>
